<?xml version="1.0" ?>
<!-- =================================================================================== -->
<!-- |    This document was autogenerated by xacro from rosbot2.xacro                  | -->
<!-- |    EDITING THIS FILE BY HAND IS NOT RECOMMENDED                                 | -->
<!-- =================================================================================== -->
<robot name="ROSbot">
  <gazebo>
    <plugin filename="libgazebo_ros_diff_drive.so" name="skid_steer_drive">
      <updateRate>10</updateRate>
      <!-- Number of wheel pairs -->
      <numWheelPairs>2</numWheelPairs>
      <leftJoint>front_left_wheel_hinge</leftJoint>
      <rightJoint>front_right_wheel_hinge</rightJoint>
      <leftJoint>rear_left_wheel_hinge</leftJoint>
      <rightJoint>rear_right_wheel_hinge</rightJoint>
      <!-- kinematics -->
      <wheelSeparation>0.24</wheelSeparation>
      <wheelSeparation>0.24</wheelSeparation>
      <wheelDiameter>0.08</wheelDiameter>
      <wheelDiameter>0.08</wheelDiameter>
      <!-- limits -->
      <wheelAcceleration>2.5</wheelAcceleration>
      <wheelTorque>0.5</wheelTorque>
      <!-- output -->
      <commandTopic>cmd_vel</commandTopic>
      <odometryTopic>odom</odometryTopic>
      <odometryFrame>odom</odometryFrame>
      <robotBaseFrame>base_link</robotBaseFrame>
      <publishOdom>true</publishOdom>
      <publishOdomTF>true</publishOdomTF>
      <publishWheelTF>true</publishWheelTF>
      <publishWheelJointState>true</publishWheelJointState>
      <odometrySource>world</odometrySource>
      <legacyMode>false</legacyMode>
    </plugin>
  </gazebo>
  <gazebo>
    <plugin filename="libgazebo_ros_control.so" name="gazebo_ros_control">
      <legacyModeNS>true</legacyModeNS>
    </plugin>
  </gazebo>
  <gazebo reference="base_link">
    <material>Gazebo/White</material>
  </gazebo>
  <gazebo reference="top_cover">
    <material>Gazebo/Red</material>
  </gazebo>
  <gazebo reference="laser">
    <material>Gazebo/Black</material>
  </gazebo>
  <gazebo reference="camera_link">
    <material>Gazebo/Black</material>
  </gazebo>
  <gazebo reference="front_left_wheel">
    <material>Gazebo/Black</material>
  </gazebo>
  <gazebo reference="front_right_wheel">
    <material>Gazebo/Black</material>
  </gazebo>
  <gazebo reference="rear_left_wheel">
    <material>Gazebo/Black</material>
  </gazebo>
  <gazebo reference="rear_right_wheel">
    <material>Gazebo/Black</material>
  </gazebo>
  <!-- astra -->
  <gazebo reference="camera_link">
    <sensor name="astra_camera" type="depth">
      <always_on>true</always_on>
      <visualize>true</visualize>
      <camera>
        <horizontal_fov>1.3962634</horizontal_fov>
        <image>
          <width>160</width>
          <height>120</height>
          <format>R8G8B8</format>
        </image>
        <depth_camera>

        </depth_camera>
        <clip>
          <near>0.02</near>
          <far>10</far>
        </clip>
        <noise>
          <type>gaussian</type>
          <mean>0.0</mean>
          <stddev>0.007</stddev>
        </noise>
      </camera>
      <plugin filename="libgazebo_ros_camera.so" name="astra_camera">
        <alwaysOn>true</alwaysOn>
        <updateRate>10.0</updateRate>
        <cameraName>camera</cameraName>
        <frameName>camera_depth_frame</frameName>
        <imageTopicName>image</imageTopicName>
        <cameraInfoTopicName>camera_info</cameraInfoTopicName>
        <hackBaseline>0.07</hackBaseline>
        <distortionK1>0.0</distortionK1>
        <distortionK2>0.0</distortionK2>
        <distortionK3>0.0</distortionK3>
        <distortionT1>0.0</distortionT1>
        <distortionT2>0.0</distortionT2>
        <min_depth>0.1</min_depth>
        <max_depth>8.0</max_depth>
      </plugin>
    </sensor>
  </gazebo>
  <!-- If you cant't use your GPU comment RpLidar using GPU and uncomment RpLidar using CPU 
    gazebo plugin. -->
  <!-- Noise parameters based on published spec for rplidar laser
    achieving "+-30mm" accuracy at range < 10m.  A mean of 0.0m and
    stddev of 0.01m will put 99.7% of samples within 0.03m of the true
    reading. -->
  <!-- RpLidar A2 using CPU -->
  <!-- <sensor type="gpu_ray" name="rp_lidar"> -->
  <!-- <gazebo reference="laser_link">
    <sensor type="ray" name="rp_lidar">
      <pose>0 0 0.5 0 0 0</pose>
      <visualize>false</visualize>
      <update_rate>10</update_rate>
      <ray>
        <scan>
          <horizontal>
            <samples>400</samples>
            <resolution>1</resolution>
            <min_angle>-3.14159265</min_angle>
            <max_angle>3.14159265</max_angle>
          </horizontal>
        </scan>
        <range>
          <min>0.25</min>
          <max>12.0</max>
          <resolution>0.02</resolution>
        </range>
        <noise>
          <type>gaussian</type>
          <mean>0.0</mean>
          <stddev>0.01</stddev>
        </noise>
      </ray>
      <plugin name="rp_lidar" filename="libgazebo_ros_ray_sensor.so">
        <topicName>scan</topicName>
        <frameName>laser</frameName>
      </plugin>
    </sensor>
  </gazebo>  -->
  <!-- RpLidar A3 using CPU -->
  <!-- <sensor type="gpu_ray" name="rp_lidar"> -->
  <gazebo reference="laser_link">
    <sensor name="rp_lidar" type="ray">
      <pose>0 0 0.015 0 0 0</pose>
      <visualize>false</visualize>
      <update_rate>10</update_rate>
      <ray>
        <scan>
          <horizontal>
            <samples>400</samples>
            <resolution>1</resolution>
            <min_angle>-3.14159265</min_angle>
            <max_angle>3.14159265</max_angle>
          </horizontal>
        </scan>
        <range>
          <min>0.25</min>
          <max>25.0</max>
          <resolution>0.02</resolution>
        </range>
        <noise>
          <type>gaussian</type>
          <mean>0.0</mean>
          <stddev>0.01</stddev>
        </noise>
      </ray>
      <plugin filename="libgazebo_ros_ray_sensor.so" name="rp_lidar">
        <topicName>scan</topicName>
        <frameName>laser</frameName>
      </plugin>
    </sensor>
  </gazebo>
  <gazebo reference="top_cover">
    <gravity>true</gravity>
    <sensor name="imu_sensor" type="imu">
      <always_on>true</always_on>
      <update_rate>10</update_rate>
      <visualize>true</visualize>
      <topic>imu</topic>
      <plugin filename="libgazebo_ros_imu_sensor.so" name="imu_plugin">
        <topicName>imu</topicName>
        <bodyName>imu</bodyName>
        <updateRateHZ>10.0</updateRateHZ>
        <gaussianNoise>0.0</gaussianNoise>
        <xyzOffset>0 0 0</xyzOffset>
        <rpyOffset>0 0 0</rpyOffset>
        <frameName>imu</frameName>
      </plugin>
      <pose>0 0 0 0 0 0</pose>
    </sensor>
  </gazebo>
  <gazebo reference="range_fl">
    <sensor name="sensor_ray" type="ray">
      <pose>0 0 0 0 0 0</pose>
      <update_rate>10</update_rate>
      <ray>
        <scan>
          <horizontal>
            <samples>2</samples>
            <resolution>1</resolution>
            <min_angle>-0.01</min_angle>
            <max_angle>0.01</max_angle>
          </horizontal>
          <vertical>
            <samples>2</samples>
            <resolution>1</resolution>
            <min_angle>-0.01</min_angle>
            <max_angle>0.01</max_angle>
          </vertical>
        </scan>
        <range>
          <min>0.05</min>
          <max>2.0</max>
        </range>
      </ray>
      <plugin filename="libgazebo_ros_ray_sensor.so" name="range">
        <gaussianNoise>0.005</gaussianNoise>
        <alwaysOn>true</alwaysOn>
        <updateRate>10</updateRate>
        <topicName>range/fl</topicName>
        <frameName>range_fl</frameName>
        <fov>0.1</fov>
        <radiation>ultrasound</radiation>
      </plugin>
    </sensor>
  </gazebo>
  <gazebo reference="range_fr">
    <sensor name="sensor_ray" type="ray">
      <pose>0 0 0 0 0 0</pose>
      <update_rate>10</update_rate>
      <ray>
        <scan>
          <horizontal>
            <samples>2</samples>
            <resolution>1</resolution>
            <min_angle>-0.01</min_angle>
            <max_angle>0.01</max_angle>
          </horizontal>
          <vertical>
            <samples>2</samples>
            <resolution>1</resolution>
            <min_angle>-0.01</min_angle>
            <max_angle>0.01</max_angle>
          </vertical>
        </scan>
        <range>
          <min>0.05</min>
          <max>2.0</max>
        </range>
      </ray>
      <plugin filename="libgazebo_ros_ray_sensor.so" name="range">
        <gaussianNoise>0.005</gaussianNoise>
        <alwaysOn>true</alwaysOn>
        <updateRate>10</updateRate>
        <topicName>range/fr</topicName>
        <frameName>range_fr</frameName>
        <fov>0.1</fov>
        <radiation>ultrasound</radiation>
      </plugin>
    </sensor>
  </gazebo>
  <gazebo reference="range_rl">
    <sensor name="sensor_ray" type="ray">
      <pose>0 0 0 0 0 0</pose>
      <update_rate>10</update_rate>
      <ray>
        <scan>
          <horizontal>
            <samples>2</samples>
            <resolution>1</resolution>
            <min_angle>-0.01</min_angle>
            <max_angle>0.01</max_angle>
          </horizontal>
          <vertical>
            <samples>2</samples>
            <resolution>1</resolution>
            <min_angle>-0.01</min_angle>
            <max_angle>0.01</max_angle>
          </vertical>
        </scan>
        <range>
          <min>0.05</min>
          <max>2.0</max>
        </range>
      </ray>
      <plugin filename="libgazebo_ros_ray_sensor.so" name="range">
        <gaussianNoise>0.005</gaussianNoise>
        <alwaysOn>true</alwaysOn>
        <updateRate>10</updateRate>
        <topicName>range/rl</topicName>
        <frameName>range_rl</frameName>
        <fov>0.1</fov>
        <radiation>ultrasound</radiation>
      </plugin>
    </sensor>
  </gazebo>
  <gazebo reference="range_rr">
    <sensor name="sensor_ray" type="ray">
      <pose>0 0 0 0 0 0</pose>
      <update_rate>10</update_rate>
      <ray>
        <scan>
          <horizontal>
            <samples>2</samples>
            <resolution>1</resolution>
            <min_angle>-0.01</min_angle>
            <max_angle>0.01</max_angle>
          </horizontal>
          <vertical>
            <samples>2</samples>
            <resolution>1</resolution>
            <min_angle>-0.01</min_angle>
            <max_angle>0.01</max_angle>
          </vertical>
        </scan>
        <range>
          <min>0.05</min>
          <max>2.0</max>
        </range>
      </ray>
      <plugin filename="libgazebo_ros_ray_sensor.so" name="range">
        <gaussianNoise>0.005</gaussianNoise>
        <alwaysOn>true</alwaysOn>
        <updateRate>10</updateRate>
        <topicName>range/rr</topicName>
        <frameName>range_rr</frameName>
        <fov>0.1</fov>
        <radiation>ultrasound</radiation>
      </plugin>
    </sensor>
  </gazebo>
  <material name="black">
    <color rgba="0.0 0.0 0.0 1.0"/>
  </material>
  <material name="blue">
    <color rgba="0.0 0.0 0.8 1.0"/>
  </material>
  <material name="green">
    <color rgba="0.0 0.8 0.0 1.0"/>
  </material>
  <material name="grey">
    <color rgba="0.2 0.2 0.2 1.0"/>
  </material>
  <material name="orange">
    <color rgba="1.0 0.4235294117647059 0.0392156862745098 1.0"/>
  </material>
  <material name="brown">
    <color rgba="0.8705882352941177 0.8117647058823529 0.7647058823529411 1.0"/>
  </material>
  <material name="red">
    <color rgba="0.8 0.0 0.0 1.0"/>
  </material>
  <material name="white">
    <color rgba="1.0 1.0 1.0 1.0"/>
  </material>
  <!--macro name="cylinder_inertia" params="m r h">
    <inertia  ixx="${m*(3*r*r+h*h)/12}" ixy = "0" ixz = "0"
      iyy="${m*(3*r*r+h*h)/12}" iyz = "0"
      izz="${m*r*r/2}"
    />
  </macro>

  <macro name="box_inertia" params="m x y z">
    <inertia  ixx="${m*(y*y+z*z)/12}" ixy = "0" ixz = "0"
      iyy="${m*(x*x+z*z)/12}" iyz = "0"
      izz="${m*(x*x+z*z)/12}"
    />
  </macro>

  <macro name="sphere_inertia" params="m r">
    <inertia  ixx="${2*m*r*r/5}" ixy = "0" ixz = "0"
      iyy="${2*m*r*r/5}" iyz = "0"
      izz="${2*m*r*r/5}"
    />
  </macro>







  <macro name="wheel" params="lr tY">

    <link name="${lr}_wheel">
      <collision>
        <origin xyz="0 0 0" rpy="0 ${PI/2} ${PI/2}" />
        <geometry>
          <cylinder length="${wheelWidth}" radius="${wheelRadius}"/>
        </geometry>
      </collision>

      <visual>
        <origin xyz="0 0 0" rpy="0 ${PI/2} ${PI/2}" />
        <geometry>
          <cylinder length="${wheelWidth}" radius="${wheelRadius}"/>
        </geometry>
        <material name="black"/>
      </visual>

      <inertial>
        <origin xyz="0 0 0" rpy="0 ${PI/2} ${PI/2}" />
        <mass value="${wheelMass}"/>
        <cylinder_inertia m="${wheelMass}" r="${wheelRadius}" h="${wheelWidth}"/>
      </inertial>
    </link>

    <gazebo reference="${lr}_wheel">
      <mu1 value="1.0"/>
      <mu2 value="1.0"/>
      <kp  value="10000000.0" />
      <kd  value="1.0" />
      <fdir1 value="1 0 0"/>
      <material>Gazebo/Black</material>
    </gazebo>


    <joint name="${lr}_wheel_hinge" type="continuous">
      <parent link="chassis"/>
      <child link="${lr}_wheel"/>
    <origin xyz="${-wheelPos+chassisLength/2} ${tY*wheelWidth/2+tY*chassisWidth/2} ${wheelRadius}" rpy="0 0 0" />
      <axis xyz="0 1 0" rpy="0 0 0" />
      <limit effort="10000" velocity="10000"/>
      <joint_properties damping="0.0" friction="0.0"/>
    </joint>


    <transmission name="${lr}_trans">
      <type>transmission_interface/SimpleTransmission</type>
      <joint name="${lr}_wheel_hinge">
        <hardwareInterface>EffortJointInterface</hardwareInterface>
      </joint>
      <actuator name="${lr}Motor">
        <hardwareInterface>EffortJointInterface</hardwareInterface>
        <mechanicalReduction>10</mechanicalReduction>
      </actuator>
    </transmission>

  </macro-->
  <link name="base_link">
    <pose>0 0 0.1 0 0 0</pose>
    <inertial>
      <mass value="5"/>
      <origin rpy=" 0 0 0" xyz="0 0 0.04"/>
      <inertia ixx="0.1" ixy="0" ixz="0" iyy="0.05" iyz="0" izz="0.1"/>
    </inertial>
    <collision name="collision">
      <origin rpy="0 0 0" xyz="0 0 0.02"/>
      <geometry>
        <box size="0.20 0.15 0.04"/>
      </geometry>
    </collision>
    <visual name="visual">
      <origin rpy=" 1.5707 0 1.5707" xyz="0 0 -0.02"/>
      <geometry>
        <mesh filename="package://rosbot_description/meshes/box.dae" scale="0.001 0.001 0.001"/>
      </geometry>
    </visual>
  </link>
  <joint name="top_cover_joint" type="fixed">
    <axis xyz="0 1 0"/>
    <origin rpy="0 0 0" xyz="0 0 0"/>
    <parent link="base_link"/>
    <child link="top_cover"/>
  </joint>
  <link name="top_cover">
    <pose>0 0 0 0 0 0</pose>
    <inertial>
      <mass value="0.01"/>
      <origin rpy=" 0 0 0" xyz="0 0 0.055"/>
      <inertia ixx="0.1" ixy="0" ixz="0" iyy="0.05" iyz="0" izz="0.1"/>
    </inertial>
    <visual name="visual">
      <origin rpy=" 1.5707 0 1.5707" xyz="0 0 0.055"/>
      <geometry>
        <mesh filename="package://rosbot_description/meshes/upper.dae" scale="0.001 0.001 0.001"/>
      </geometry>
    </visual>
  </link>
  <link name="front_left_wheel">
    <pose>0.053 0.11 0.02 0 0 0</pose>
    <collision name="collision">
      <origin rpy="0 0 1.5707" xyz="0 0 0"/>
      <geometry>
        <mesh filename="package://rosbot_description/meshes/wheel-v2.stl" scale="0.001 0.001 0.001"/>
      </geometry>
      <surface>
        <friction>
          <ode>
            <mu>10</mu>
            <mu2>10</mu2>
          </ode>
        </friction>
      </surface>
    </collision>
    <visual name="front_left_wheel_visual">
      <origin rpy="0 0 1.5707" xyz="0 0 0"/>
      <geometry>
        <mesh filename="package://rosbot_description/meshes/wheel.dae" scale="0.001 0.001 0.001"/>
      </geometry>
    </visual>
    <inertial>
      <origin rpy="0 0 0" xyz="0 0 0"/>
      <mass value="0.01"/>
      <inertia ixx="0.001" ixy="0.0001" ixz="0.0001" iyy="0.001" iyz="0.0001" izz="0.001"/>
    </inertial>
  </link>
  <link name="front_right_wheel">
    <pose>0.053 -0.11 0.02 0 0 0</pose>
    <collision name="collision">
      <origin rpy="0 0 -1.5707" xyz="0 0 0"/>
      <geometry>
        <mesh filename="package://rosbot_description/meshes/wheel-v2.stl" scale="0.001 0.001 0.001"/>
      </geometry>
      <surface>
        <friction>
          <ode>
            <mu>10</mu>
            <mu2>10</mu2>
          </ode>
        </friction>
      </surface>
    </collision>
    <visual name="front_right_wheel_visual">
      <origin rpy="0 0 -1.5707" xyz="0 0 0"/>
      <geometry>
        <mesh filename="package://rosbot_description/meshes/wheel.dae" scale="0.001 0.001 0.001"/>
      </geometry>
    </visual>
    <inertial>
      <origin rpy="0 0 0" xyz="0 0 0"/>
      <mass value="0.01"/>
      <inertia ixx="0.001" ixy="0.0001" ixz="0.0001" iyy="0.001" iyz="0.0001" izz="0.001"/>
    </inertial>
  </link>
  <link name="rear_left_wheel">
    <pose>-0.053 0.11 0.02 0 0 0</pose>
    <collision name="collision">
      <origin rpy="0 0 1.5707" xyz="0 0 0"/>
      <geometry>
        <mesh filename="package://rosbot_description/meshes/wheel-v2.stl" scale="0.001 0.001 0.001"/>
      </geometry>
      <surface>
        <friction>
          <ode>
            <mu>10</mu>
            <mu2>10</mu2>
          </ode>
        </friction>
      </surface>
    </collision>
    <visual name="rear_left_wheel_visual">
      <origin rpy="0 0 1.5707" xyz="0 0 0"/>
      <geometry>
        <mesh filename="package://rosbot_description/meshes/wheel.dae" scale="0.001 0.001 0.001"/>
      </geometry>
    </visual>
    <inertial>
      <origin rpy="0 0 0" xyz="0 0 0"/>
      <mass value="0.01"/>
      <inertia ixx="0.001" ixy="0.0001" ixz="0.0001" iyy="0.001" iyz="0.0001" izz="0.001"/>
    </inertial>
  </link>
  <link name="rear_right_wheel">
    <pose>-0.053 -0.11 0.02 0 0</pose>
    <collision name="collision">
      <origin rpy="0 0 -1.5707" xyz="0 0 0"/>
      <geometry>
        <mesh filename="package://rosbot_description/meshes/wheel-v2.stl" scale="0.001 0.001 0.001"/>
      </geometry>
      <surface>
        <friction>
          <ode>
            <mu>10</mu>
            <mu2>10</mu2>
          </ode>
        </friction>
      </surface>
    </collision>
    <visual name="rear_right_wheel_visual">
      <origin rpy="0 0 -1.5707" xyz="0 0 0"/>
      <geometry>
        <mesh filename="package://rosbot_description/meshes/wheel.dae" scale="0.001 0.001 0.001"/>
      </geometry>
    </visual>
    <inertial>
      <origin rpy="0 0 0" xyz="0 0 0"/>
      <mass value="0.01"/>
      <inertia ixx="0.001" ixy="0.0001" ixz="0.0001" iyy="0.001" iyz="0.0001" izz="0.001"/>
    </inertial>
  </link>
  <joint name="front_left_wheel_hinge" type="continuous">
    <origin rpy="0 0 0" xyz="0 0 0"/>
    <child link="front_left_wheel"/>
    <parent link="base_link"/>
    <axis rpy="0 0 0" xyz="0 1 0"/>
    <limit effort="1" velocity="10"/>
    <joint_properties damping="5.0" friction="1.0"/>
  </joint>
  <transmission name="front_left_wheel_trans" type="SimpleTransmission">
    <type>transmission_interface/SimpleTransmission</type>
    <actuator name="front_left_wheel_motor">
      <mechanicalReduction>1</mechanicalReduction>
    </actuator>
    <joint name="front_left_wheel_hinge">
      <hardwareInterface>hardware_interface/EffortJointInterface</hardwareInterface>
    </joint>
  </transmission>
  <joint name="front_right_wheel_hinge" type="continuous">
    <origin rpy="0 0 0" xyz="0 0 0"/>
    <child link="front_right_wheel"/>
    <parent link="base_link"/>
    <axis rpy="0 0 0" xyz="0 1 0"/>
    <limit effort="1" velocity="10"/>
    <joint_properties damping="5.0" friction="1.0"/>
  </joint>
  <transmission name="front_right_wheel_trans" type="SimpleTransmission">
    <type>transmission_interface/SimpleTransmission</type>
    <actuator name="front_right_wheel_motor">
      <mechanicalReduction>1</mechanicalReduction>
    </actuator>
    <joint name="front_right_wheel_hinge">
      <hardwareInterface>hardware_interface/EffortJointInterface</hardwareInterface>
    </joint>
  </transmission>
  <joint name="rear_left_wheel_hinge" type="continuous">
    <origin rpy="0 0 0" xyz="0 0 0"/>
    <child link="rear_left_wheel"/>
    <parent link="base_link"/>
    <axis rpy="0 0 0" xyz="0 1 0"/>
    <limit effort="1" velocity="10"/>
    <joint_properties damping="5.0" friction="1.0"/>
  </joint>
  <transmission name="rear_left_wheel_trans" type="SimpleTransmission">
    <type>transmission_interface/SimpleTransmission</type>
    <actuator name="rear_left_wheel_motor">
      <mechanicalReduction>1</mechanicalReduction>
    </actuator>
    <joint name="rear_left_wheel_hinge">
      <hardwareInterface>hardware_interface/EffortJointInterface</hardwareInterface>
    </joint>
  </transmission>
  <joint name="rear_right_wheel_hinge" type="continuous">
    <origin rpy="0 0 0" xyz="0 0 0"/>
    <child link="rear_right_wheel"/>
    <parent link="base_link"/>
    <axis rpy="0 0 0" xyz="0 1 0"/>
    <limit effort="1" velocity="10"/>
    <joint_properties damping="5.0" friction="1.0"/>
  </joint>
  <transmission name="rear_right_wheel_trans" type="SimpleTransmission">
    <type>transmission_interface/SimpleTransmission</type>
    <actuator name="rear_right_wheel_motor">
      <mechanicalReduction>1</mechanicalReduction>
    </actuator>
    <joint name="rear_right_wheel_hinge">
      <hardwareInterface>hardware_interface/EffortJointInterface</hardwareInterface>
    </joint>
  </transmission>
  <!-- Orbbec Astra RGBD Camera -->
  <joint name="camera_joint" type="fixed">
    <axis xyz="0 0 0"/>
    <origin rpy="0 0 0" xyz="-0.03 0 0.18"/>
    <parent link="base_link"/>
    <child link="camera_link"/>
  </joint>
  <link name="camera_link">
    <pose>0 0 0 0 0 0</pose>
    <collision>
      <origin rpy="0 0 0" xyz="0.02 0 0"/>
      <geometry>
        0
        
        <box size="0.001 0.001 0.001"/>
      </geometry>
    </collision>
    <visual>
      <origin rpy="1.5707 0 1.5707" xyz="-0.01 0 -0.03"/>
      <geometry>
        <mesh filename="package://rosbot_description/meshes/astra.dae" scale="0.001 0.001 0.001"/>
      </geometry>
    </visual>
    <inertial>
      <mass value="1e-4"/>
      <origin rpy="0 0 0" xyz="0 0 0"/>
      <inertia ixx="0.1" ixy="0" ixz="0" iyy="0.05" iyz="0" izz="0.1"/>
    </inertial>
  </link>
  <joint name="camera_optical_joint" type="fixed">
    <origin rpy="-1.5707963267948966 0 -1.5707963267948966" xyz="0 0 0"/>
    <parent link="camera_link"/>
    <child link="camera_rgb_frame"/>
  </joint>
  <link name="camera_rgb_frame">
  </link>
  <joint name="camera_depth_joint" type="fixed">
    <origin rpy="-1.5707963267948966 0 -1.5707963267948966" xyz="0 0 0"/>
    <parent link="camera_link"/>
    <child link="camera_depth_frame"/>
  </joint>
  <link name="camera_depth_frame">
  </link>
  <joint name="laser_joint" type="fixed">
    <axis xyz="0 1 0"/>
    <origin rpy="0 0 3.14" xyz="0.02 0 0.058"/>
    <parent link="base_link"/>
    <child link="laser_link"/>
  </joint>
  <!-- rplidar Laser -->
  <!-- maybe use A3 -->
  <link name="laser_link">
    <pose>0 0 0 0 0 0</pose>
    <collision>
      <origin rpy="1.5707 0 4.71" xyz="0 0 0"/>
      <geometry>
        <mesh filename="package://rosbot_description/meshes/rplidar.dae" scale="0.001 0.001 0.001"/>
      </geometry>
    </collision>
    <visual>
      <origin rpy="1.5707 0 4.71" xyz="0 0 0"/>
      <geometry>
        <mesh filename="package://rosbot_description/meshes/rplidar.dae" scale="0.001 0.001 0.001"/>
      </geometry>
    </visual>
    <inertial>
      <mass value="1e-4"/>
      <origin rpy="1.5707 0 4.71" xyz="0 0 0"/>
      <inertia ixx="0.1" ixy="0" ixz="0" iyy="0.05" iyz="0" izz="0.1"/>
    </inertial>
  </link>
  <joint name="range_fl_joint" type="fixed">
    <axis xyz="0 1 0"/>
    <origin rpy="0 0 0.13 " xyz="0.1 0.05 0.01"/>
    <parent link="base_link"/>
    <child link="range_fl"/>
  </joint>
  <link name="range_fl">
    <pose>0 0 0 0 0 0</pose>
    <inertial>
      <mass value="1e-4"/>
      <origin rpy="0 0 0" xyz="0 0 0"/>
      <inertia ixx="0.1" ixy="0" ixz="0" iyy="0.05" iyz="0" izz="0.1"/>
    </inertial>
  </link>
  <joint name="range_fr_joint" type="fixed">
    <axis xyz="0 1 0"/>
    <origin rpy="0 0 -0.13 " xyz="0.1 -0.05 0.01"/>
    <parent link="base_link"/>
    <child link="range_fr"/>
  </joint>
  <link name="range_fr">
    <pose>0 0 0 0 0 0</pose>
    <inertial>
      <mass value="1e-4"/>
      <origin rpy="0 0 0" xyz="0 0 0"/>
      <inertia ixx="0.1" ixy="0" ixz="0" iyy="0.05" iyz="0" izz="0.1"/>
    </inertial>
  </link>
  <joint name="range_rl_joint" type="fixed">
    <axis xyz="0 1 0"/>
    <origin rpy="0 0 3.01 " xyz="-0.1 0.05 0.01"/>
    <parent link="base_link"/>
    <child link="range_rl"/>
  </joint>
  <link name="range_rl">
    <pose>0 0 0 0 0 0</pose>
    <inertial>
      <mass value="1e-4"/>
      <origin rpy="0 0 0" xyz="0 0 0"/>
      <inertia ixx="0.1" ixy="0" ixz="0" iyy="0.05" iyz="0" izz="0.1"/>
    </inertial>
  </link>
  <joint name="range_rr_joint" type="fixed">
    <axis xyz="0 1 0"/>
    <origin rpy="0 0 3.27 " xyz="-0.1 -0.05 0.01"/>
    <parent link="base_link"/>
    <child link="range_rr"/>
  </joint>
  <link name="range_rr">
    <pose>0 0 0 0 0 0</pose>
    <inertial>
      <mass value="1e-4"/>
      <origin rpy="0 0 0" xyz="0 0 0"/>
      <inertia ixx="0.1" ixy="0" ixz="0" iyy="0.05" iyz="0" izz="0.1"/>
    </inertial>
  </link>
</robot>
